Workbook

Sheet MA
C2: K=2 | D2: K=3 | E2: k=4 | F2: k=5 | G2: k=6 | I2: K=2 | J2: K=3 | K2: k=4 | L2: K=5 | M2: K=6 | P2: K=2 | Q2: K=3 | R2: K=4 | S2: K=5 | T2: K=6
A3: Semana | B3: yt | C3: Medias moviles | D3: Medias moviles | E3: Medias moviles | F3: Medias moviles | G3: Medias moviles | I3: Error2 | J3: Error2 | K3: Error2 | L3: Error2 | M3: Error2 | O3: MSE | P3: =AVERAGE(I7:I24) -> 376.70833 | Q3: =AVERAGE(J8:J24) -> 240.33333 | R3: =AVERAGE(K9:K24) -> 238.77734 | S3: =AVERAGE(L10:L24) -> 279.11467 | T3: =AVERAGE(M11:M24) -> 247.15079
A4: 0 | O4: RMSE | P4: =SQRT(P3) -> 19.408976 | Q4: =SQRT(Q3) -> 15.502688 | R4: =SQRT(R3) -> 15.452422 | S4: =SQRT(S3) -> 16.706725 | T4: =SQRT(T3) -> 15.72103
A5: 1 | B5: 53
A6: 2 | B6: 85
A7: 3 | B7: 43 | C7: =AVERAGE(B5:B6) -> 69 | I7: =(B7-C7)^2 -> 676
A8: 4 | B8: 55 | C8: =AVERAGE(B6:B7) -> 64 | D8: =AVERAGE(B5:B7) -> 60.333333 | I8: =(B8-C8)^2 -> 81 | J8: =(B8-D8)^2 -> 28.444444
A9: 5 | B9: 58 | C9: =AVERAGE(B7:B8) -> 49 | D9: =AVERAGE(B6:B8) -> 61 | E9: =AVERAGE(B5:B8) -> 59 | I9: =(B9-C9)^2 -> 81 | J9: =(B9-D9)^2 -> 9 | K9: =(B9-E9)^2 -> 1
A10: 6 | B10: 73 | C10: =AVERAGE(B8:B9) -> 56.5 | D10: =AVERAGE(B7:B9) -> 52 | E10: =AVERAGE(B6:B9) -> 60.25 | F10: =AVERAGE(B5:B9) -> 58.8 | I10: =(B10-C10)^2 -> 272.25 | J10: =(B10-D10)^2 -> 441 | K10: =(B10-E10)^2 -> 162.5625 | L10: =(B10-F10)^2 -> 201.64
A11: 7 | B11: 35 | C11: =AVERAGE(B9:B10) -> 65.5 | D11: =AVERAGE(B8:B10) -> 62 | E11: =AVERAGE(B7:B10) -> 57.25 | F11: =AVERAGE(B6:B10) -> 62.8 | G11: =AVERAGE(B5:B10) -> 61.166667 | I11: =(B11-C11)^2 -> 930.25 | J11: =(B11-D11)^2 -> 729 | K11: =(B11-E11)^2 -> 495.0625 | L11: =(B11-F11)^2 -> 772.84 | M11: =(B11-G11)^2 -> 684.69444
A12: 8 | B12: 86 | C12: =AVERAGE(B10:B11) -> 54 | D12: =AVERAGE(B9:B11) -> 55.333333 | E12: =AVERAGE(B8:B11) -> 55.25 | F12: =AVERAGE(B7:B11) -> 52.8 | G12: =AVERAGE(B6:B11) -> 58.166667 | I12: =(B12-C12)^2 -> 1024 | J12: =(B12-D12)^2 -> 940.44444 | K12: =(B12-E12)^2 -> 945.5625 | L12: =(B12-F12)^2 -> 1102.24 | M12: =(B12-G12)^2 -> 774.69444
A13: 9 | B13: 67 | C13: =AVERAGE(B11:B12) -> 60.5 | D13: =AVERAGE(B10:B12) -> 64.666667 | E13: =AVERAGE(B9:B12) -> 63 | F13: =AVERAGE(B8:B12) -> 61.4 | G13: =AVERAGE(B7:B12) -> 58.333333 | I13: =(B13-C13)^2 -> 42.25 | J13: =(B13-D13)^2 -> 5.4444444 | K13: =(B13-E13)^2 -> 16 | L13: =(B13-F13)^2 -> 31.36 | M13: =(B13-G13)^2 -> 75.111111
A14: 10 | B14: 39 | C14: =AVERAGE(B12:B13) -> 76.5 | D14: =AVERAGE(B11:B13) -> 62.666667 | E14: =AVERAGE(B10:B13) -> 65.25 | F14: =AVERAGE(B9:B13) -> 63.8 | G14: =AVERAGE(B8:B13) -> 62.333333 | I14: =(B14-C14)^2 -> 1406.25 | J14: =(B14-D14)^2 -> 560.11111 | K14: =(B14-E14)^2 -> 689.0625 | L14: =(B14-F14)^2 -> 615.04 | M14: =(B14-G14)^2 -> 544.44444
A15: 11 | B15: 81 | C15: =AVERAGE(B13:B14) -> 53 | D15: =AVERAGE(B12:B14) -> 64 | E15: =AVERAGE(B11:B14) -> 56.75 | F15: =AVERAGE(B10:B14) -> 60 | G15: =AVERAGE(B9:B14) -> 59.666667 | I15: =(B15-C15)^2 -> 784 | J15: =(B15-D15)^2 -> 289 | K15: =(B15-E15)^2 -> 588.0625 | L15: =(B15-F15)^2 -> 441 | M15: =(B15-G15)^2 -> 455.11111
A16: 12 | B16: 67 | C16: =AVERAGE(B14:B15) -> 60 | D16: =AVERAGE(B13:B15) -> 62.333333 | E16: =AVERAGE(B12:B15) -> 68.25 | F16: =AVERAGE(B11:B15) -> 61.6 | G16: =AVERAGE(B10:B15) -> 63.5 | I16: =(B16-C16)^2 -> 49 | J16: =(B16-D16)^2 -> 21.777778 | K16: =(B16-E16)^2 -> 1.5625 | L16: =(B16-F16)^2 -> 29.16 | M16: =(B16-G16)^2 -> 12.25
A17: 13 | B17: 58 | C17: =AVERAGE(B15:B16) -> 74 | D17: =AVERAGE(B14:B16) -> 62.333333 | E17: =AVERAGE(B13:B16) -> 63.5 | F17: =AVERAGE(B12:B16) -> 68 | G17: =AVERAGE(B11:B16) -> 62.5 | I17: =(B17-C17)^2 -> 256 | J17: =(B17-D17)^2 -> 18.777778 | K17: =(B17-E17)^2 -> 30.25 | L17: =(B17-F17)^2 -> 100 | M17: =(B17-G17)^2 -> 20.25
A18: 14 | B18: 51 | C18: =AVERAGE(B16:B17) -> 62.5 | D18: =AVERAGE(B15:B17) -> 68.666667 | E18: =AVERAGE(B14:B17) -> 61.25 | F18: =AVERAGE(B13:B17) -> 62.4 | G18: =AVERAGE(B12:B17) -> 66.333333 | I18: =(B18-C18)^2 -> 132.25 | J18: =(B18-D18)^2 -> 312.11111 | K18: =(B18-E18)^2 -> 105.0625 | L18: =(B18-F18)^2 -> 129.96 | M18: =(B18-G18)^2 -> 235.11111
A19: 15 | B19: 67 | C19: =AVERAGE(B17:B18) -> 54.5 | D19: =AVERAGE(B16:B18) -> 58.666667 | E19: =AVERAGE(B15:B18) -> 64.25 | F19: =AVERAGE(B14:B18) -> 59.2 | G19: =AVERAGE(B13:B18) -> 60.5 | I19: =(B19-C19)^2 -> 156.25 | J19: =(B19-D19)^2 -> 69.444444 | K19: =(B19-E19)^2 -> 7.5625 | L19: =(B19-F19)^2 -> 60.84 | M19: =(B19-G19)^2 -> 42.25
A20: 16 | B20: 51 | C20: =AVERAGE(B18:B19) -> 59 | D20: =AVERAGE(B17:B19) -> 58.666667 | E20: =AVERAGE(B16:B19) -> 60.75 | F20: =AVERAGE(B15:B19) -> 64.8 | G20: =AVERAGE(B14:B19) -> 60.5 | I20: =(B20-C20)^2 -> 64 | J20: =(B20-D20)^2 -> 58.777778 | K20: =(B20-E20)^2 -> 95.0625 | L20: =(B20-F20)^2 -> 190.44 | M20: =(B20-G20)^2 -> 90.25
A21: 17 | B21: 65 | C21: =AVERAGE(B19:B20) -> 59 | D21: =AVERAGE(B18:B20) -> 56.333333 | E21: =AVERAGE(B17:B20) -> 56.75 | F21: =AVERAGE(B16:B20) -> 58.8 | G21: =AVERAGE(B15:B20) -> 62.5 | I21: =(B21-C21)^2 -> 36 | J21: =(B21-D21)^2 -> 75.111111 | K21: =(B21-E21)^2 -> 68.0625 | L21: =(B21-F21)^2 -> 38.44 | M21: =(B21-G21)^2 -> 6.25
A22: 18 | B22: 56 | C22: =AVERAGE(B20:B21) -> 58 | D22: =AVERAGE(B19:B21) -> 61 | E22: =AVERAGE(B18:B21) -> 58.5 | F22: =AVERAGE(B17:B21) -> 58.4 | G22: =AVERAGE(B16:B21) -> 59.833333 | I22: =(B22-C22)^2 -> 4 | J22: =(B22-D22)^2 -> 25 | K22: =(B22-E22)^2 -> 6.25 | L22: =(B22-F22)^2 -> 5.76 | M22: =(B22-G22)^2 -> 14.694444
... A24: 20 | B24: 75 | C24: =AVERAGE(B22:B23) -> 51 | D24: =AVERAGE(B21:B23) -> 55.666667 | E24: =AVERAGE(B20:B23) -> 54.5 | F24: =AVERAGE(B19:B23) -> 57 | G24: =AVERAGE(B18:B23) -> 56 | I24: =(B24-C24)^2 -> 576 | J24: =(B24-D24)^2 -> 373.77778 | K24: =(B24-E24)^2 -> 420.25 | L24: =(B24-F24)^2 -> 324 | M24: =(B24-G24)^2 -> 361
A25: 21 | C25: =AVERAGE(B23:B24) -> 60.5 | D25: =AVERAGE(B22:B24) -> 59 | E25: =AVERAGE(B21:B24) -> 60.5 | F25: =AVERAGE(B20:B24) -> 58.6 | G25: =AVERAGE(B19:B24) -> 60
A26: 22 | C26: =(B24+C25)/2 -> 67.75 | D26: =(B23+B24+C25)/3 -> 60.5 | E26: =(B22+B23+B24+E25)/4 -> 59.375 | F26: =(B21+B22+B23+B24+F25)/5 -> 60.12 | G26: =(B20+B21+B22+B23+G24+G25)/6 -> 55.666667
A27: 23 | C27: =(C25+C26)/2 -> 64.125 | D27: =(B24+C25+C26)/3 -> 67.75 | E27: =(B23+B24+E25+E26)/4 -> 60.21875 | F27: =(B22+B23+B24+F25+F26)/5 -> 59.144 | G27: =(B21+B22+B23+B24+G25+G26)/6 -> 59.611111
A28: 24 | C28: =(C26+C27)/2 -> 65.9375 | D28: =(C25+C26+C27)/3 -> 64.125 | E28: =AVERAGE(B24+E25+E26+E27)/4 -> 63.773438 | F28: =(B23+B24+F25+F26+F27)/5 -> 59.7728 | G28: =(B22+B23+B24+G25+G26+G27)/6 -> 58.712963

Sheet SES
A1: Semana | B1: yt | C1: Yhat_t | D1: Error2 | E1: alpha | F1: MSE | G1: RMSE
A2: 0 | E2: 0.07086688 | F2: =AVERAGE(D4:D22) -> 253.23316 | G2: =SQRT(F2) -> 15.913301
A3: 1 | B3: 53 | C3: 53
A4: 2 | B4: 85 | C4: =$E$2*B3+(1-$E$2)*C3 -> 53 | D4: =(B4-C4)^2 -> 1024
A5: 3 | B5: 43 | C5: =$E$2*B4+(1-$E$2)*C4 -> 55.26774 | D5: =(B5-C5)^2 -> 150.49745
A6: 4 | B6: 55 | C6: =$E$2*B5+(1-$E$2)*C5 -> 54.398364 | D6: =(B6-C6)^2 -> 0.36196624
A7: 5 | B7: 58 | C7: =$E$2*B6+(1-$E$2)*C6 -> 54.441 | D7: =(B7-C7)^2 -> 12.666483
A8: 6 | B8: 73 | C8: =$E$2*B7+(1-$E$2)*C7 -> 54.693215 | D8: =(B8-C8)^2 -> 335.13838
A9: 7 | B9: 35 | C9: =$E$2*B8+(1-$E$2)*C8 -> 55.99056 | D9: =(B9-C9)^2 -> 440.6036
A10: 8 | B10: 86 | C10: =$E$2*B9+(1-$E$2)*C9 -> 54.503024 | D10: =(B10-C10)^2 -> 992.05948
A11: 9 | B11: 67 | C11: =$E$2*B10+(1-$E$2)*C10 -> 56.735117 | D11: =(B11-C11)^2 -> 105.36783
A12: 10 | B12: 39 | C12: =$E$2*B11+(1-$E$2)*C11 -> 57.462557 | D12: =(B12-C12)^2 -> 340.86601
A13: 11 | B13: 81 | C13: =$E$2*B12+(1-$E$2)*C12 -> 56.154173 | D13: =(B13-C13)^2 -> 617.31511
A14: 12 | B14: 67 | C14: =$E$2*B13+(1-$E$2)*C13 -> 57.914919 | D14: =(B14-C14)^2 -> 82.53869
A15: 13 | B15: 58 | C15: =$E$2*B14+(1-$E$2)*C14 -> 58.558751 | D15: =(B15-C15)^2 -> 0.31220234
... A22: 20 | B22: 75 | C22: =$E$2*B21+(1-$E$2)*C21 -> 57.514099 | D22: =(B22-C22)^2 -> 305.75673
A23: 21 | C23: =$E$2*B22+(1-$E$2)*C22 -> 58.75327 | D23: =($B$22-C23)^2 -> 263.95623
A24: 22 | C24: =$E$2*B22+(1-$E$2)*C23 -> 59.904625 | D24: =($B$22-C24)^2 -> 227.87034
A25: 23 | C25: =$E$2*B22+(1-$E$2)*C24 -> 60.974387 | D25: =($B$22-C25)^2 -> 196.71781
A26: 24 | C26: =$E$2*B22+(1-$E$2)*C25 -> 61.968339 | D26: =($B$22-C26)^2 -> 169.82419

Sheet HOLT
A1: Semana | B1: yt | C1: Ft | D1: Tt | E1: Yhat_t+m | F1: Error | G1: Error2 | I1: MSE | J1: RMSE | K1: ALPHA | L1: GAMMA | M1: m
A2: 0 | I2: =AVERAGE(G4:G22) -> 17.397149 | J2: =SQRT(I2) -> 4.1709889 | K2: 0.83309124 | L2: 0.52928422 | M2: 1
A3: 1 | B3: 53 | C3: 53 | D3: 0 | M3: 2
A4: 2 | B4: 85 | C4: =$K$2*B4+(1-$K$2)*(C3+D3) -> 79.65892 | D4: =$L$2*(C4-C3)+(1-$L$2)*D3 -> 14.110146 | E4: =C4+D4 -> 93.769065 | F4: =B4-E4 -> -8.7690655 | G4: =F4^2 -> 76.89651 | M4: 3
A5: 3 | B5: 43 | C5: =$K$2*B5+(1-$K$2)*(C4+D4) -> 51.473802 | D5: =$L$2*(C5-C4)+(1-$L$2)*D4 -> -8.2760703 | E5: =C5+D5 -> 43.197731 | F5: =B5-E5 -> -0.19773131 | G5: =F5^2 -> 0.039097669 | M5: 4
A6: 4 | B6: 55 | C6: =$K$2*B6+(1-$K$2)*(C5+D5) -> 53.030098 | D6: =$L$2*(C6-C5)+(1-$L$2)*D5 -> -3.0719537 | E6: =C6+D6 -> 49.958144 | F6: =B6-E6 -> 5.0418557 | G6: =F6^2 -> 25.420309
A7: 5 | B7: 58 | C7: =$K$2*B7+(1-$K$2)*(C6+D6) -> 56.657744 | D7: =$L$2*(C7-C6)+(1-$L$2)*D6 -> 0.47403867 | E7: =C7+D7 -> 57.131783 | F7: =B7-E7 -> 0.86821746 | G7: =F7^2 -> 0.75380156
A8: 6 | B8: 73 | C8: =$K$2*B8+(1-$K$2)*(C7+D7) -> 70.351456 | D8: =$L$2*(C8-C7)+(1-$L$2)*D7 -> 7.471003 | E8: =C8+D8 -> 77.822459 | F8: =B8-E8 -> -4.8224586 | G8: =F8^2 -> 23.256107
A9: 7 | B9: 35 | C9: =$K$2*B9+(1-$K$2)*(C8+D8) -> 42.147443 | D9: =$L$2*(C9-C8)+(1-$L$2)*D8 -> -11.41122 | E9: =C9+D9 -> 30.736224 | F9: =B9-E9 -> 4.2637765 | G9: =F9^2 -> 18.17979
A10: 8 | B10: 86 | C10: =$K$2*B10+(1-$K$2)*(C9+D9) -> 76.775992 | D10: =$L$2*(C10-C9)+(1-$L$2)*D9 -> 12.956903 | E10: =C10+D10 -> 89.732895 | F10: =B10-E10 -> -3.7328951 | G10: =F10^2 -> 13.934506
A11: 9 | B11: 67 | C11: =$K$2*B11+(1-$K$2)*(C10+D10) -> 70.794319 | D11: =$L$2*(C11-C10)+(1-$L$2)*D10 -> 2.9330139 | E11: =C11+D11 -> 73.727333 | F11: =B11-E11 -> -6.7273331 | G11: =F11^2 -> 45.257011
A12: 10 | B12: 39 | C12: =$K$2*B12+(1-$K$2)*(C11+D11) -> 44.796296 | D12: =$L$2*(C12-C11)+(1-$L$2)*D11 -> -12.379728 | E12: =C12+D12 -> 32.416568 | F12: =B12-E12 -> 6.5834317 | G12: =F12^2 -> 43.341573
A13: 11 | B13: 81 | C13: =$K$2*B13+(1-$K$2)*(C12+D12) -> 72.891 | D13: =$L$2*(C13-C12)+(1-$L$2)*D12 -> 9.0427504 | E13: =C13+D13 -> 81.93375 | F13: =B13-E13 -> -0.93375026 | G13: =F13^2 -> 0.87188956
A14: 12 | B14: 67 | C14: =$K$2*B14+(1-$K$2)*(C13+D13) -> 69.492574 | D14: =$L$2*(C14-C13)+(1-$L$2)*D13 -> 2.4578319 | E14: =C14+D14 -> 71.950406 | F14: =B14-E14 -> -4.9504056 | G14: =F14^2 -> 24.506516
A15: 13 | B15: 58 | C15: =$K$2*B15+(1-$K$2)*(C14+D14) -> 60.328445 | D15: =$L$2*(C15-C14)+(1-$L$2)*D14 -> -3.6934886 | E15: =C15+D15 -> 56.634956 | F15: =B15-E15 -> 1.3650437 | G15: =F15^2 -> 1.8633443
A16: 14 | B16: 51 | C16: =$K$2*B16+(1-$K$2)*(C15+D15) -> 51.940524 | D16: =$L$2*(C16-C15)+(1-$L$2)*D15 -> -6.1781778 | E16: =C16+D16 -> 45.762346 | F16: =B16-E16 -> 5.2376542 | G16: =F16^2 -> 27.433022
A17: 15 | B17: 67 | C17: =$K$2*B17+(1-$K$2)*(C16+D16) -> 63.45525 | D17: =$L$2*(C17-C16)+(1-$L$2)*D16 -> 3.1863971 | E17: =C17+D17 -> 66.641647 | F17: =B17-E17 -> 0.35835336 | G17: =F17^2 -> 0.12841713
... A22: 20 | B22: 75 | C22: =$K$2*B22+(1-$K$2)*(C21+D21) -> 69.483757 | D22: =$L$2*(C22-C21)+(1-$L$2)*D21 -> 8.793573 | E22: =C22+D22 -> 78.27733 | F22: =B22-E22 -> -3.2773303 | G22: =F22^2 -> 10.740894
A23: 21 | E23: =$C$22+M2*$D$22 -> 78.27733
A24: 22 | E24: =$C$22+M3*$D$22 -> 87.070903
A25: 23 | E25: =$C$22+M4*$D$22 -> 95.864476
A26: 24 | E26: =$C$22+M5*$D$22 -> 104.65805

Sheet H-WINTERS
C1: Suavización | D1: Estacionalidad | E1: Tendencia
A2: Semana | B2: yt | C2: Ft | D2: St | E2: Tt | F2: Normalización | G2: Yhat_t | H2: Error | I2: Error2 | J2: |Error/yt| | L2: MSE | M2: RMSE | N2: MAPE | O2: ALPHA | P2: BETA | Q2: GAMMA
A3: -3 | F3: =P39 -> 1.0123506 | L3: =AVERAGE(_xlfn.ANCHORARRAY(I7)) -> 25.31678 | M3: =SQRT(L3) -> 5.0315782 | N3: =AVERAGE(J7:J26) -> 0.072945746 | O3: 0.20151646 | P3: 0 | Q3: 0.075578304
A4: -2 | F4: =P40 -> 1.0293135
A5: -1 | F5: =P41 -> 0.88226777
A6: 0 | C6: =B42 -> 69.45625 | E6: =B41 -> 0.9375 | F6: =P42 -> 1.0760682
A7: 1 | B7: 53 | C7: =$O$3*(B7/F3)+(1-$O$3)*(C6+E6) -> 66.758324 | D7: =$P$3*(B7/C7)+(1-$P$3)*F3 -> 1.0123506 | E7: =$Q$3*(C7-C6)+(1-$Q$3)*E6 -> 0.66274065 | F7: =D7/SUM($D$7:$D$10)*4 -> 1.0123506 | G7: =(C7+A7*E7)*F3 -> 68.253753 | H7: =C7-G7 -> -1.4954291 | I7: {=H7:H26^2} -> 2.2363083 | J7: =ABS(H7/B7) -> 0.028215644
A8: 2 | B8: 85 | C8: =$O$3*(B8/F4)+(1-$O$3)*(C7+E7) -> 70.475701 | D8: =$P$3*(B8/C8)+(1-$P$3)*F4 -> 1.0293135 | E8: =$Q$3*(C8-C7)+(1-$Q$3)*E7 -> 0.89360492 | F8: =D8/SUM($D$7:$D$10)*4 -> 1.0293135 | G8: =(C8+A8*E8)*F4 -> 74.381187 | H8: =C8-G8 -> -3.9054858 | I8: 15.252819 | J8: =ABS(H8/B8) -> 0.045946892
A9: 3 | B9: 43 | C9: =$O$3*(B9/F5)+(1-$O$3)*(C8+E8) -> 66.808733 | D9: =$P$3*(B9/C9)+(1-$P$3)*F5 -> 0.88226777 | E9: =$Q$3*(C9-C8)+(1-$Q$3)*E8 -> 0.54892454 | F9: =D9/SUM($D$7:$D$10)*4 -> 0.88226777 | G9: =(C9+A9*E9)*F5 -> 60.396088 | H9: =C9-G9 -> 6.4126455 | I9: 41.122022 | J9: =ABS(H9/B9) -> 0.14913129
A10: 4 | B10: 55 | C10: =$O$3*(B10/F6)+(1-$O$3)*(C9+E9) -> 64.083891 | D10: =$P$3*(B10/C10)+(1-$P$3)*F6 -> 1.0760682 | E10: =$Q$3*(C10-C9)+(1-$Q$3)*E9 -> 0.30149879 | F10: =D10/SUM($D$7:$D$10)*4 -> 1.0760682 | G10: =(C10+A10*E10)*F6 -> 70.25637 | H10: =C10-G10 -> -6.172479 | I10: 38.099497 | J10: =ABS(H10/B10) -> 0.11222689
A11: 5 | B11: 58 | C11: =$O$3*(B11/F7)+(1-$O$3)*(C10+E10) -> 62.956037 | D11: =$P$3*(B11/C11)+(1-$P$3)*F7 -> 1.0123506 | E11: =$Q$3*(C11-C10)+(1-$Q$3)*E10 -> 0.19347073 | F11: =D11/SUM($D$11:$D$14)*4 -> 1.0123506 | G11: =(C11+A11*E11)*F7 -> 64.712881 | H11: =C11-G11 -> -1.7568438 | I11: 3.0865003 | J11: =ABS(H11/B11) -> 0.030290411
A12: 6 | B12: 73 | C12: =$O$3*(B12/F8)+(1-$O$3)*(C11+E11) -> 64.715603 | D12: =$P$3*(B12/C12)+(1-$P$3)*F8 -> 1.0293135 | E12: =$Q$3*(C12-C11)+(1-$Q$3)*E11 -> 0.31183356 | F12: =D12/SUM($D$11:$D$14)*4 -> 1.0293135 | G12: =(C12+A12*E12)*F8 -> 68.538488 | H12: =C12-G12 -> -3.8228851 | I12: 14.614451 | J12: =ABS(H12/B12) -> 0.05236829
A13: 7 | B13: 35 | C13: =$O$3*(B13/F9)+(1-$O$3)*(C12+E12) -> 59.917596 | D13: =$P$3*(B13/C13)+(1-$P$3)*F9 -> 0.88226777 | E13: =$Q$3*(C13-C12)+(1-$Q$3)*E12 -> -0.074359542 | F13: =D13/SUM($D$11:$D$14)*4 -> 0.88226777 | G13: =(C13+A13*E13)*F9 -> 52.404129 | H13: =C13-G13 -> 7.513467 | I13: 56.452187 | J13: =ABS(H13/B13) -> 0.21467049
A14: 8 | B14: 86 | C14: =$O$3*(B14/F10)+(1-$O$3)*(C13+E13) -> 63.889152 | D14: =$P$3*(B14/C14)+(1-$P$3)*F10 -> 1.0760682 | E14: =$Q$3*(C14-C13)+(1-$Q$3)*E13 -> 0.23142395 | F14: =D14/SUM($D$11:$D$14)*4 -> 1.0760682 | G14: =(C14+A14*E14)*F10 -> 70.741308 | H14: =C14-G14 -> -6.8521562 | I14: 46.952044 | J14: =ABS(H14/B14) -> 0.079676235
A15: 9 | B15: 67 | C15: =$O$3*(B15/F11)+(1-$O$3)*(C14+E14) -> 64.536109 | D15: =$P$3*(B15/C15)+(1-$P$3)*F11 -> 1.0123506 | E15: =$Q$3*(C15-C14)+(1-$Q$3)*E14 -> 0.26282924 | F15: =D15/SUM($D$15:$D$18)*4 -> 1.0123506 | G15: =(C15+A15*E15)*F11 -> 67.727845 | H15: =C15-G15 -> -3.1917356 | I15: 10.187176 | J15: =ABS(H15/B15) -> 0.047637845
A16: 10 | B16: 39 | C16: =$O$3*(B16/F12)+(1-$O$3)*(C15+E15) -> 59.37621 | D16: =$P$3*(B16/C16)+(1-$P$3)*F12 -> 1.0293135 | E16: =$Q$3*(C16-C15)+(1-$Q$3)*E15 -> -0.14701138 | F16: =D16/SUM($D$15:$D$18)*4 -> 1.0293135 | G16: =(C16+A16*E16)*F12 -> 59.603524 | H16: =C16-G16 -> -0.22731425 | I16: 0.051671768 | J16: =ABS(H16/B16) -> 0.0058285705
A17: 11 | B17: 81 | C17: =$O$3*(B17/F13)+(1-$O$3)*(C16+E16) -> 65.794537 | D17: =$P$3*(B17/C17)+(1-$P$3)*F13 -> 0.88226777 | E17: =$Q$3*(C17-C16)+(1-$Q$3)*E16 -> 0.34918575 | F17: =D17/SUM($D$15:$D$18)*4 -> 0.88226777 | G17: =(C17+A17*E17)*F13 -> 61.437228 | H17: =C17-G17 -> 4.3573086 | I17: 18.986138 | J17: =ABS(H17/B17) -> 0.053793933
A18: 12 | B18: 67 | C18: =$O$3*(B18/F14)+(1-$O$3)*(C17+E17) -> 65.361837 | D18: =$P$3*(B18/C18)+(1-$P$3)*F14 -> 1.0760682 | E18: =$Q$3*(C18-C17)+(1-$Q$3)*E17 -> 0.29009212 | F18: =D18/SUM($D$15:$D$18)*4 -> 1.0760682 | G18: =(C18+A18*E18)*F14 -> 74.079701 | H18: =C18-G18 -> -8.7178639 | I18: 76.001151 | J18: =ABS(H18/B18) -> 0.13011737
A19: 13 | B19: 58 | C19: =$O$3*(B19/F15)+(1-$O$3)*(C18+E18) -> 63.967347 | D19: =$P$3*(B19/C19)+(1-$P$3)*F15 -> 1.0123506 | E19: =$Q$3*(C19-C18)+(1-$Q$3)*E18 -> 0.16277432 | F19: =D19/SUM($D$19:$D$22)*4 -> 1.0123506 | G19: =(C19+A19*E19)*F15 -> 66.899581 | H19: =C19-G19 -> -2.9322339 | I19: 8.5979956 | J19: =ABS(H19/B19) -> 0.050555757
A20: 14 | B20: 51 | C20: =$O$3*(B20/F16)+(1-$O$3)*(C19+E19) -> 61.191501 | D20: =$P$3*(B20/C20)+(1-$P$3)*F16 -> 1.0293135 | E20: =$Q$3*(C20-C19)+(1-$Q$3)*E19 -> -0.059321624 | F20: =D20/SUM($D$19:$D$22)*4 -> 1.0293135 | G20: =(C20+A20*E20)*F16 -> 62.130388 | H20: =C20-G20 -> -0.93888699 | I20: 0.88150878 | J20: =ABS(H20/B20) -> 0.018409549
A21: 15 | B21: 67 | C21: =$O$3*(B21/F17)+(1-$O$3)*(C20+E20) -> 64.116333 | D21: =$P$3*(B21/C21)+(1-$P$3)*F17 -> 0.88226777 | E21: =$Q$3*(C21-C20)+(1-$Q$3)*E20 -> 0.16621561 | F21: =D21/SUM($D$19:$D$22)*4 -> 0.88226777 | G21: =(C21+A21*E21)*F17 -> 58.767474 | H21: =C21-G21 -> 5.3488584 | I21: 28.610286 | J21: =ABS(H21/B21) -> 0.079833708
A22: 16 | B22: 51 | C22: =$O$3*(B22/F18)+(1-$O$3)*(C21+E21) -> 60.879382 | D22: =$P$3*(B22/C22)+(1-$P$3)*F18 -> 1.0760682 | E22: =$Q$3*(C22-C21)+(1-$Q$3)*E21 -> -0.090989918 | F22: =D22/SUM($D$19:$D$22)*4 -> 1.0760682 | G22: =(C22+A22*E22)*F18 -> 63.943785 | H22: =C22-G22 -> -3.0644031 | I22: 9.3905663 | J22: =ABS(H22/B22) -> 0.060086335
A23: 17 | B23: 65 | C23: =$O$3*(B23/F19)+(1-$O$3)*(C22+E22) -> 61.477299 | D23: =$P$3*(B23/C23)+(1-$P$3)*F19 -> 1.0123506 | E23: =$Q$3*(C23-C22)+(1-$Q$3)*E22 -> -0.038923489 | F23: =D23/SUM($D$23:$D$26)*4 -> 1.0123506 | G23: =(C23+A23*E23)*F19 -> 61.566707 | H23: =C23-G23 -> -0.089407931 | I23: 0.0079937782 | J23: =ABS(H23/B23) -> 0.0013755066
A24: 18 | B24: 56 | C24: =$O$3*(B24/F20)+(1-$O$3)*(C23+E23) -> 60.021074 | D24: =$P$3*(B24/C24)+(1-$P$3)*F20 -> 1.0293135 | E24: =$Q$3*(C24-C23)+(1-$Q$3)*E23 -> -0.14604074 | F24: =D24/SUM($D$23:$D$26)*4 -> 1.0293135 | G24: =(C24+A24*E24)*F20 -> 59.074709 | H24: =C24-G24 -> 0.94636524 | I24: 0.89560717 | J24: =ABS(H24/B24) -> 0.016899379
A25: 19 | B25: 46 | C25: =$O$3*(B25/F21)+(1-$O$3)*(C24+E24) -> 58.315968 | D25: =$P$3*(B25/C25)+(1-$P$3)*F21 -> 0.88226777 | E25: =$Q$3*(C25-C24)+(1-$Q$3)*E24 -> -0.2638723 | F25: =D25/SUM($D$23:$D$26)*4 -> 0.88226777 | G25: =(C25+A25*E25)*F21 -> 47.026985 | H25: =C25-G25 -> 11.288983 | I25: 127.44114 | J25: =ABS(H25/B25) -> 0.24541268
A26: 20 | B26: 75 | C26: =$O$3*(B26/F22)+(1-$O$3)*(C25+E25) -> 60.398974 | D26: =$P$3*(B26/C26)+(1-$P$3)*F22 -> 1.0760682 | E26: =$Q$3*(C26-C25)+(1-$Q$3)*E25 -> -0.086499189 | F26: =D26/SUM($D$23:$D$26)*4 -> 1.0760682 | G26: =(C26+A26*E26)*F22 -> 63.131835 | H26: =C26-G26 -> -2.7328605 | I26: 7.4685265 | J26: =ABS(H26/B26) -> 0.03643814
A27: 21 | G27: =($C$26+A27*$E$26)*F23 -> 59.306018
A28: 22 | G28: =($C$26+A28*$E$26)*F24 -> 60.210712
A29: 23 | G29: =($C$26+A29*$E$26)*F25 -> 51.532813
A30: 24 | G30: =($C$26+A30*$E$26)*F26 -> 62.759519
B33: Mes 1 | C33: Mes 2 | D33: Mes 3 | E33: Mes 4 | F33: Mes 5
A34: 1 | B34: 53 | C34: 58 | D34: 67 | E34: 58 | F34: 65 | I34: 1 | J34: 5 | K34: 9 | L34: 13 | M34: 17
A35: 2 | B35: 85 | C35: 73 | D35: 39 | E35: 51 | F35: 56 | I35: 2 | J35: 6 | K35: 10 | L35: 14 | M35: 18
A36: 3 | B36: 43 | C36: 35 | D36: 81 | E36: 67 | F36: 46 | I36: 3 | J36: 7 | K36: 11 | L36: 15 | M36: 19
A37: 4 | B37: 55 | C37: 86 | D37: 67 | E37: 51 | F37: 75 | I37: 4 | J37: 8 | K37: 12 | L37: 16 | M37: 20
A38: promedios | B38: =AVERAGE(B34:B37) -> 59 | C38: =AVERAGE(C34:C37) -> 63 | D38: =AVERAGE(D34:D37) -> 63.5 | E38: =AVERAGE(E34:E37) -> 56.75 | F38: =AVERAGE(F34:F37) -> 60.5 | I38: Factores estacionales | O38: Promedios | P38: Normalización
A39: Promedio Total | B39: =AVERAGE(B38:F38) -> 60.55 | I39: =B34/($B$42-(COUNTA($B$34:$F$37)-I34)*$B$41) -> 1.0262616 | J39: =C34/($B$42-(COUNTA($B$34:$F$37)-J34)*$B$41) -> 1.0470495 | K39: =D34/($B$42-(COUNTA($B$34:$F$37)-K34)*$B$41) -> 1.1328331 | L39: =E34/($B$42-(COUNTA($B$34:$F$37)-L34)*$B$41) -> 0.9221902 | M39: =F34/($B$42-(COUNTA($B$34:$F$37)-M34)*$B$41) -> 0.97533527 | O39: =AVERAGE(I39:M39) -> 1.020734 | P39: =(O39/$O$43)*4 -> 1.0123506
I40: =B35/($B$42-(COUNTA($B$34:$F$37)-I35)*$B$41) -> 1.6165458 | J40: =C35/($B$42-(COUNTA($B$34:$F$37)-J35)*$B$41) -> 1.2959059 | K40: =D35/($B$42-(COUNTA($B$34:$F$37)-K35)*$B$41) -> 0.64912098 | L40: =E35/($B$42-(COUNTA($B$34:$F$37)-L35)*$B$41) -> 0.79898169 | M40: =F35/($B$42-(COUNTA($B$34:$F$37)-M35)*$B$41) -> 0.8286322 | O40: =AVERAGE(I40:M40) -> 1.0378373 | P40: =(O40/$O$43)*4 -> 1.0293135
A41: T0 | B41: =(F38-E38)/4 -> 0.9375 | I41: =B36/($B$42-(COUNTA($B$34:$F$37)-I36)*$B$41) -> 0.80345673 | J41: =C36/($B$42-(COUNTA($B$34:$F$37)-J36)*$B$41) -> 0.61115355 | K41: =D36/($B$42-(COUNTA($B$34:$F$37)-K36)*$B$41) -> 1.3274608 | L41: =E36/($B$42-(COUNTA($B$34:$F$37)-L36)*$B$41) -> 1.0344495 | M41: =F36/($B$42-(COUNTA($B$34:$F$37)-M36)*$B$41) -> 0.67134908 | O41: =AVERAGE(I41:M41) -> 0.88957393 | P41: =(O41/$O$43)*4 -> 0.88226777
A42: F0 | B42: =B39+B41*((COUNTA(B34:F37)-1)/2) -> 69.45625 | I42: =B37/($B$42-(COUNTA($B$34:$F$37)-I37)*$B$41) -> 1.0099851 | J42: =C37/($B$42-(COUNTA($B$34:$F$37)-J37)*$B$41) -> 1.4775046 | K42: =D37/($B$42-(COUNTA($B$34:$F$37)-K37)*$B$41) -> 1.0814083 | L42: =E37/($B$42-(COUNTA($B$34:$F$37)-L37)*$B$41) -> 0.77618187 | M42: =F37/($B$42-(COUNTA($B$34:$F$37)-M37)*$B$41) -> 1.0798164 | O42: =AVERAGE(I42:M42) -> 1.0849792 | P42: =(O42/$O$43)*4 -> 1.0760682
...

Sheet COMPARACIÓN
C1: Medias Moviles | D1: SES | E1: HOLT | F1: H-WINTERS
A2: Semana | B2: yt | C2: K=4 | D2: =SES!C1 -> Yhat_t | E2: =HOLT!E1 -> Yhat_t+m | F2: ='H-WINTERS'!G2 -> Yhat_t | I2: =MA!R2 -> K=4 | J2: SES | K2: HOLT | L2: H-WINTERS
A3: 0 | H3: =MA!O3 -> MSE | I3: =MA!R3 -> 238.77734 | J3: =SES!$F$2 -> 253.23316 | K3: =HOLT!$I$2 -> 17.397149 | L3: ='H-WINTERS'!$L$3 -> 25.31678
A4: 1 | B4: 53 | D4: =SES!C3 -> 53 | F4: ='H-WINTERS'!G7 -> 68.253753 | H4: =MA!O4 -> RMSE | I4: =MA!R4 -> 15.452422 | J4: =SES!$G$2 -> 15.913301 | K4: =HOLT!$J$2 -> 4.1709889 | L4: ='H-WINTERS'!$M$3 -> 5.0315782
A5: 2 | B5: 85 | D5: =SES!C4 -> 53 | E5: =HOLT!E4 -> 93.769065 | F5: ='H-WINTERS'!G8 -> 74.381187
A6: 3 | B6: 43 | D6: =SES!C5 -> 55.26774 | E6: =HOLT!E5 -> 43.197731 | F6: ='H-WINTERS'!G9 -> 60.396088
A7: 4 | B7: 55 | D7: =SES!C6 -> 54.398364 | E7: =HOLT!E6 -> 49.958144 | F7: ='H-WINTERS'!G10 -> 70.25637
A8: 5 | B8: 58 | C8: =MA!E9 -> 59 | D8: =SES!C7 -> 54.441 | E8: =HOLT!E7 -> 57.131783 | F8: ='H-WINTERS'!G11 -> 64.712881
A9: 6 | B9: 73 | C9: =MA!E10 -> 60.25 | D9: =SES!C8 -> 54.693215 | E9: =HOLT!E8 -> 77.822459 | F9: ='H-WINTERS'!G12 -> 68.538488
A10: 7 | B10: 35 | C10: =MA!E11 -> 57.25 | D10: =SES!C9 -> 55.99056 | E10: =HOLT!E9 -> 30.736224 | F10: ='H-WINTERS'!G13 -> 52.404129
A11: 8 | B11: 86 | C11: =MA!E12 -> 55.25 | D11: =SES!C10 -> 54.503024 | E11: =HOLT!E10 -> 89.732895 | F11: ='H-WINTERS'!G14 -> 70.741308
A12: 9 | B12: 67 | C12: =MA!E13 -> 63 | D12: =SES!C11 -> 56.735117 | E12: =HOLT!E11 -> 73.727333 | F12: ='H-WINTERS'!G15 -> 67.727845
A13: 10 | B13: 39 | C13: =MA!E14 -> 65.25 | D13: =SES!C12 -> 57.462557 | E13: =HOLT!E12 -> 32.416568 | F13: ='H-WINTERS'!G16 -> 59.603524
A14: 11 | B14: 81 | C14: =MA!E15 -> 56.75 | D14: =SES!C13 -> 56.154173 | E14: =HOLT!E13 -> 81.93375 | F14: ='H-WINTERS'!G17 -> 61.437228
A15: 12 | B15: 67 | C15: =MA!E16 -> 68.25 | D15: =SES!C14 -> 57.914919 | E15: =HOLT!E14 -> 71.950406 | F15: ='H-WINTERS'!G18 -> 74.079701
A16: 13 | B16: 58 | C16: =MA!E17 -> 63.5 | D16: =SES!C15 -> 58.558751 | E16: =HOLT!E15 -> 56.634956 | F16: ='H-WINTERS'!G19 -> 66.899581
A17: 14 | B17: 51 | C17: =MA!E18 -> 61.25 | D17: =SES!C16 -> 58.519154 | E17: =HOLT!E16 -> 45.762346 | F17: ='H-WINTERS'!G20 -> 62.130388
A18: 15 | B18: 67 | C18: =MA!E19 -> 64.25 | D18: =SES!C17 -> 57.986295 | E18: =HOLT!E17 -> 66.641647 | F18: ='H-WINTERS'!G21 -> 58.767474
A19: 16 | B19: 51 | C19: =MA!E20 -> 60.75 | D19: =SES!C18 -> 58.625068 | E19: =HOLT!E18 -> 49.900065 | F19: ='H-WINTERS'!G22 -> 63.943785
... A23: 20 | B23: 75 | C23: =MA!E24 -> 54.5 | D23: =SES!C22 -> 57.514099 | E23: =HOLT!E22 -> 78.27733 | F23: ='H-WINTERS'!G26 -> 63.131835
A24: 21 | C24: =MA!E25 -> 60.5 | D24: =SES!C23 -> 58.75327 | E24: =HOLT!E23 -> 78.27733 | F24: ='H-WINTERS'!G27 -> 59.306018
A25: 22 | C25: =MA!E26 -> 59.375 | D25: =SES!C24 -> 59.904625 | E25: =HOLT!E24 -> 87.070903 | F25: ='H-WINTERS'!G28 -> 60.210712
A26: 23 | C26: =MA!E27 -> 60.21875 | D26: =SES!C25 -> 60.974387 | E26: =HOLT!E25 -> 95.864476 | F26: ='H-WINTERS'!G29 -> 51.532813
A27: 24 | C27: =MA!E28 -> 63.773438 | D27: =SES!C26 -> 61.968339 | E27: =HOLT!E26 -> 104.65805 | F27: ='H-WINTERS'!G30 -> 62.759519

Sheet EDA
A1: Semana | B1: yt
A2: 0
A3: 1 | B3: 53 | D3: Y(t)
A4: 2 | B4: 85 | D4: Mean | E4: 60.55
A5: 3 | B5: 43 | D5: Standard Error | E5: 3.2899168
A6: 4 | B6: 55 | D6: Median | E6: 58
A7: 5 | B7: 58 | D7: Mode | E7: 67
A8: 6 | B8: 73 | D8: Standard Deviation | E8: 14.712955
A9: 7 | B9: 35 | D9: Sample Variance | E9: 216.47105
A10: 8 | B10: 86 | D10: Range | E10: 51
A11: 9 | B11: 67 | D11: Minimum | E11: 35
A12: 10 | B12: 39 | D12: Maximum | E12: 86
A13: 11 | B13: 81 | D13: Count | E13: 20
A14: 12 | B14: 67
A15: 13 | B15: 58
A16: 14 | B16: 51
A17: 15 | B17: 67
A18: 16 | B18: 51
A19: 17 | B19: 65
A20: 18 | B20: 56
A21: 19 | B21: 46
A22: 20 | B22: 75
A23: 21
A24: 22
A25: 23
A26: 24
